Workbook

Sheet Read Me
A8: Healthcare Application Rationalization — Sample Dataset
A10: 20 real healthcare and enterprise technology products with synthetic organization data
A12: Prepared for: | B12: AppRat AI Hackathon
A13: As of: | B13: 46248
A15: This workbook is an analysis-ready test portfolio for a fictional global health system. Product names, vendors, and public capability descriptions are real; every organization-specific value is synthetic. No stakeholder interviews or patient-level data were used.
A19: Sheet | B19: Purpose | C19: Use in prototype
A20: App Inventory | B20: One row per application; primary upload table | C20: Model input
A21: User Profiles | B21: Access-level entitlement and 90-day usage counts | C21: Model input
A22: Capability Map | B22: Many-to-many capabilities, tasks, roles, and criticality | C22: Model input
A23: Risks | B23: Detailed risks, scores, mitigations, owners, and status | C23: Model input
A24: TCO | B24: Cost components, annual TCO, avoidable cost, and transition cost | C24: Model input
A25: Dependencies | B25: Application, data, authentication, workflow, and infrastructure dependencies | C25: Model input
A26: Performance & Roadmap | B26: KPIs, lifecycle, releases, support, and contract timing | C26: Model input
A27: Assumptions | B27: Definitions, thresholds, and synthetic-data controls | C27: Reference
A28: Data Dictionary | B28: Mapping to every required data area | C28: Reference
A29: Sources | B29: Official product pages used for public facts | C29: Reference

Sheet App Inventory
A1: App ID | B1: Application Name | C1: Short Name | D1: Description | E1: Vendor | F1: Category | G1: Tool Type | H1: Commercial Model | I1: Hosting Model | J1: Platform | K1: Development / Configuration Language | L1: Primary Business Unit | M1: Application Owner | N1: Owner Role | O1: Owner Email | P1: Technical SME | Q1: SME Role | R1: SME Email | S1: Vendor Product URL | T1: Vendor Support URL | U1: Primary Capability | V1: Critical Operation Flag | W1: Business Criticality | X1: Business Value Score (1-5) | Y1: Business Value Rationale | Z1: Data Classification | AA1: Entitled Users | AB1: Active Users (90d) | AC1: Utilization Rate | AD1: Annual TCO | AE1: Avoidable Annual Cost | AF1: Highest Risk | AG1: Dependency Count | AH1: Availability (12mo) | AI1: SLA Target | AJ1: Performance Status | AK1: Lifecycle Stage | AL1: Next Major Update | AM1: Contract Renewal Date | AN1: Evidence Confidence | AO1: Evidence Sources | AP1: Data Status
A2: APP-001 | B2: Epic | C2: Epic EHR | D2: Enterprise electronic health record supporting clinical documentation, computerized provider order entry, patient records, revenue cycle workflows, and patient engagement. | E2: Epic Systems Corporation | F2: Electronic Health Record | G2: Application Platform | H2: Commercial off-the-shelf | I2: Private cloud / vendor-managed hosting (synthetic deployment) | J2: Web, Windows, and mobile clinical clients; proprietary EHR platform | K2: Vendor proprietary; customer integrations use HL7, FHIR, and APIs | L2: Clinical Operations | M2: Maya Chen (synthetic) | N2: Chief Medical Information Officer | O2: maya.chen@northstarhealth.example | P2: Alex Romero (synthetic) | Q2: EHR Platform Architect | R2: alex.romero@northstarhealth.example | S2: https://www.epic.com/about/ | T2: https://userweb.epic.com/ | U2: Patient record management | V2: Yes | W2: Critical | X2: 5 | Y2: System of record for inpatient and emergency care; direct impact to clinical operations and patient safety. | Z2: PHI / PII | AA2: =SUMIF('User Profiles'!$A$2:$A$41,$A2,'User Profiles'!$E$2:$E$41) -> 32500 | AB2: =SUMIF('User Profiles'!$A$2:$A$41,$A2,'User Profiles'!$F$2:$F$41) -> 29400 | AC2: =IFERROR(AB2/AA2,0) -> 0.90461538 | AD2: =SUMIF(TCO!$A$2:$A$21,$A2,TCO!$I$2:$I$21) -> 8750000 | AE2: =SUMIF(TCO!$A$2:$A$21,$A2,TCO!$J$2:$J$21) -> 0 | AF2: High | AG2: =COUNTIF(Dependencies!$B$2:$B$33,$A2) -> 3 | AH2: =INDEX('Performance & Roadmap'!$C$2:$C$21,MATCH($A2,'Performance & Roadmap'!$A$2:$A$21,0)) -> 0.9998 | AI2: =INDEX('Performance & Roadmap'!$D$2:$D$21,MATCH($A2,'Performance & Roadmap'!$A$2:$A$21,0)) -> 0.999 | AJ2: =INDEX('Performance & Roadmap'!$K$2:$K$21,MATCH($A2,'Performance & Roadmap'!$A$2:$A$21,0)) -> Meets | AK2: =INDEX('Performance & Roadmap'!$M$2:$M$21,MATCH($A2,'Performance & Roadmap'!$A$2:$A$21,0)) -> Strategic Invest | AL2: =INDEX('Performance & Roadmap'!$O$2:$O$21,MATCH($A2,'Performance & Roadmap'!$A$2:$A$21,0)) -> 2027-03-15 | AM2: =INDEX('Performance & Roadmap'!$Q$2:$Q$21,MATCH($A2,'Performance & Roadmap'!$A$2:$A$21,0)) -> 2027-06-30 | AN2: High | AO2: CMDB; IAM/SSO; contracts; service desk; scans; integration catalog — all synthetic | AP2: Real product; synthetic organization data
A3: APP-002 | B3: Oracle Health EHR | C3: Oracle EHR | D3: Enterprise EHR supporting clinical documentation, orders, patient timelines, care coordination, and clinical decision support for acquired hospitals. | E3: Oracle Corporation | F3: Electronic Health Record | G3: Application Platform | H3: Commercial off-the-shelf | I3: Vendor cloud / hosted (synthetic deployment) | J3: Browser and mobile clients; proprietary Oracle Health platform | K3: Vendor proprietary; integrations use HL7, FHIR, and APIs | L3: Clinical Operations | M3: Aaron Patel (synthetic) | N3: VP, Clinical Informatics | O3: aaron.patel@northstarhealth.example | P3: Samira Malik (synthetic) | Q3: Oracle Health Technical Lead | R3: samira.malik@northstarhealth.example | S3: https://www.oracle.com/health/clinical-suite/electronic-health-record/ | T3: https://support.oracle.com/ | U3: Patient record management | V3: Yes | W3: Critical | X3: 4 | Y3: Supports three acquired hospitals but duplicates core EHR capabilities and has below-target adoption and performance. | Z3: PHI / PII | AA3: =SUMIF('User Profiles'!$A$2:$A$41,$A3,'User Profiles'!$E$2:$E$41) -> 10200 | AB3: =SUMIF('User Profiles'!$A$2:$A$41,$A3,'User Profiles'!$F$2:$F$41) -> 7200 | AC3: =IFERROR(AB3/AA3,0) -> 0.70588235 | AD3: =SUMIF(TCO!$A$2:$A$21,$A3,TCO!$I$2:$I$21) -> 6500000 | AE3: =SUMIF(TCO!$A$2:$A$21,$A3,TCO!$J$2:$J$21) -> 4400000 | AF3: High | AG3: =COUNTIF(Dependencies!$B$2:$B$33,$A3) -> 2 | AH3: =INDEX('Performance & Roadmap'!$C$2:$C$21,MATCH($A3,'Performance & Roadmap'!$A$2:$A$21,0)) -> 0.9985 | AI3: =INDEX('Performance & Roadmap'!$D$2:$D$21,MATCH($A3,'Performance & Roadmap'!$A$2:$A$21,0)) -> 0.999 | AJ3: =INDEX('Performance & Roadmap'!$K$2:$K$21,MATCH($A3,'Performance & Roadmap'!$A$2:$A$21,0)) -> Below | AK3: =INDEX('Performance & Roadmap'!$M$2:$M$21,MATCH($A3,'Performance & Roadmap'!$A$2:$A$21,0)) -> Consolidation Candidate | AL3: =INDEX('Performance & Roadmap'!$O$2:$O$21,MATCH($A3,'Performance & Roadmap'!$A$2:$A$21,0)) -> 2027-02-01 | AM3: =INDEX('Performance & Roadmap'!$Q$2:$Q$21,MATCH($A3,'Performance & Roadmap'!$A$2:$A$21,0)) -> 2027-01-31 | AN3: High | AO3: CMDB; IAM/SSO; contracts; service desk; scans; integration catalog — all synthetic | AP3: Real product; synthetic organization data
A4: APP-003 | B4: athenaOne | C4: athenaOne | D4: Cloud-based ambulatory suite combining EHR, practice management, revenue cycle, and patient engagement capabilities. | E4: athenahealth, Inc. | F4: Electronic Health Record | G4: SaaS | H4: Commercial SaaS | I4: Vendor-managed SaaS | J4: Web and mobile | K4: Vendor proprietary; APIs, HL7, and FHIR integrations | L4: Ambulatory Operations | M4: Priya Shah (synthetic) | N4: VP, Ambulatory Operations | O4: priya.shah@northstarhealth.example | P4: Cameron Wells (synthetic) | Q4: Ambulatory Applications Architect | R4: cameron.wells@northstarhealth.example | S4: https://www.athenahealth.com/solutions/athenaone | T4: https://www.athenahealth.com/about/contact-us | U4: Ambulatory care delivery | V4: Yes | W4: High | X4: 4 | Y4: Purpose-fit for independent ambulatory affiliates with high adoption and a distinct collections-based operating model. | Z4: PHI / PII | AA4: =SUMIF('User Profiles'!$A$2:$A$41,$A4,'User Profiles'!$E$2:$E$41) -> 3000 | AB4: =SUMIF('User Profiles'!$A$2:$A$41,$A4,'User Profiles'!$F$2:$F$41) -> 2560 | AC4: =IFERROR(AB4/AA4,0) -> 0.85333333 | AD4: =SUMIF(TCO!$A$2:$A$21,$A4,TCO!$I$2:$I$21) -> 1500000 | AE4: =SUMIF(TCO!$A$2:$A$21,$A4,TCO!$J$2:$J$21) -> 0 | AF4: Medium | AG4: =COUNTIF(Dependencies!$B$2:$B$33,$A4) -> 1 | AH4: =INDEX('Performance & Roadmap'!$C$2:$C$21,MATCH($A4,'Performance & Roadmap'!$A$2:$A$21,0)) -> 0.9995 | AI4: =INDEX('Performance & Roadmap'!$D$2:$D$21,MATCH($A4,'Performance & Roadmap'!$A$2:$A$21,0)) -> 0.999 | AJ4: =INDEX('Performance & Roadmap'!$K$2:$K$21,MATCH($A4,'Performance & Roadmap'!$A$2:$A$21,0)) -> Meets | AK4: =INDEX('Performance & Roadmap'!$M$2:$M$21,MATCH($A4,'Performance & Roadmap'!$A$2:$A$21,0)) -> Active | AL4: =INDEX('Performance & Roadmap'!$O$2:$O$21,MATCH($A4,'Performance & Roadmap'!$A$2:$A$21,0)) -> 2026-11-15 | AM4: =INDEX('Performance & Roadmap'!$Q$2:$Q$21,MATCH($A4,'Performance & Roadmap'!$A$2:$A$21,0)) -> 2027-03-31 | AN4: High | AO4: CMDB; IAM/SSO; contracts; service desk; scans; integration catalog — all synthetic | AP4: Real product; synthetic organization data
A5: APP-004 | B5: Microsoft Teams Enterprise | C5: Teams | D5: Enterprise collaboration platform for chat, channels, meetings, calling, files, and workflow integrations. | E5: Microsoft Corporation | F5: Collaboration | G5: SaaS | H5: Commercial SaaS | I5: Vendor-managed SaaS | J5: Web, Windows, macOS, iOS, and Android | K5: Vendor proprietary; Power Platform, Graph API, and webhooks for extensions | L5: Digital Workplace | M5: Lena Ortiz (synthetic) | N5: VP, Digital Workplace | O5: lena.ortiz@northstarhealth.example | P5: Noah Bennett (synthetic) | Q5: Collaboration Platform Lead | R5: noah.bennett@northstarhealth.example | S5: https://www.microsoft.com/en-us/microsoft-teams/enterprise | T5: https://support.microsoft.com/teams | U5: Enterprise collaboration | V5: No | W5: High | X5: 4 | Y5: Strategic enterprise standard integrated with identity, productivity, meetings, and security controls. | Z5: Internal / possible PHI | AA5: =SUMIF('User Profiles'!$A$2:$A$41,$A5,'User Profiles'!$E$2:$E$41) -> 41500 | AB5: =SUMIF('User Profiles'!$A$2:$A$41,$A5,'User Profiles'!$F$2:$F$41) -> 34400 | AC5: =IFERROR(AB5/AA5,0) -> 0.82891566 | AD5: =SUMIF(TCO!$A$2:$A$21,$A5,TCO!$I$2:$I$21) -> 3830000 | AE5: =SUMIF(TCO!$A$2:$A$21,$A5,TCO!$J$2:$J$21) -> 0 | AF5: Medium | AG5: =COUNTIF(Dependencies!$B$2:$B$33,$A5) -> 1 | AH5: =INDEX('Performance & Roadmap'!$C$2:$C$21,MATCH($A5,'Performance & Roadmap'!$A$2:$A$21,0)) -> 0.9997 | AI5: =INDEX('Performance & Roadmap'!$D$2:$D$21,MATCH($A5,'Performance & Roadmap'!$A$2:$A$21,0)) -> 0.999 | AJ5: =INDEX('Performance & Roadmap'!$K$2:$K$21,MATCH($A5,'Performance & Roadmap'!$A$2:$A$21,0)) -> Meets | AK5: =INDEX('Performance & Roadmap'!$M$2:$M$21,MATCH($A5,'Performance & Roadmap'!$A$2:$A$21,0)) -> Strategic Invest | AL5: =INDEX('Performance & Roadmap'!$O$2:$O$21,MATCH($A5,'Performance & Roadmap'!$A$2:$A$21,0)) -> 2026-10-10 | AM5: =INDEX('Performance & Roadmap'!$Q$2:$Q$21,MATCH($A5,'Performance & Roadmap'!$A$2:$A$21,0)) -> 2027-06-30 | AN5: High | AO5: CMDB; IAM/SSO; contracts; service desk; scans; integration catalog — all synthetic | AP5: Real product; synthetic organization data
A6: APP-005 | B6: Slack Enterprise Grid | C6: Slack | D6: Enterprise messaging and collaboration platform using workspaces, channels, search, file sharing, and application integrations. | E6: Salesforce, Inc. | F6: Collaboration | G6: SaaS | H6: Commercial SaaS | I6: Vendor-managed SaaS | J6: Web, desktop, iOS, and Android | K6: Vendor proprietary; APIs, webhooks, and app framework | L6: Digital Workplace | M6: Lena Ortiz (synthetic) | N6: VP, Digital Workplace | O6: lena.ortiz@northstarhealth.example | P6: Isabella Ross (synthetic) | Q6: Messaging Platform Lead | R6: isabella.ross@northstarhealth.example | S6: https://slack.com/enterprise | T6: https://slack.com/help | U6: Enterprise collaboration | V6: No | W6: Medium | X6: 3 | Y6: Useful for technology teams but duplicates enterprise messaging and collaboration capabilities already available in Teams. | Z6: Internal / possible PHI | AA6: =SUMIF('User Profiles'!$A$2:$A$41,$A6,'User Profiles'!$E$2:$E$41) -> 10800 | AB6: =SUMIF('User Profiles'!$A$2:$A$41,$A6,'User Profiles'!$F$2:$F$41) -> 5320 | AC6: =IFERROR(AB6/AA6,0) -> 0.49259259 | AD6: =SUMIF(TCO!$A$2:$A$21,$A6,TCO!$I$2:$I$21) -> 1260000 | AE6: =SUMIF(TCO!$A$2:$A$21,$A6,TCO!$J$2:$J$21) -> 820000 | AF6: High | AG6: =COUNTIF(Dependencies!$B$2:$B$33,$A6) -> 2 | AH6: =INDEX('Performance & Roadmap'!$C$2:$C$21,MATCH($A6,'Performance & Roadmap'!$A$2:$A$21,0)) -> 0.9993 | AI6: =INDEX('Performance & Roadmap'!$D$2:$D$21,MATCH($A6,'Performance & Roadmap'!$A$2:$A$21,0)) -> 0.999 | AJ6: =INDEX('Performance & Roadmap'!$K$2:$K$21,MATCH($A6,'Performance & Roadmap'!$A$2:$A$21,0)) -> Below | AK6: =INDEX('Performance & Roadmap'!$M$2:$M$21,MATCH($A6,'Performance & Roadmap'!$A$2:$A$21,0)) -> Consolidation Candidate | AL6: =INDEX('Performance & Roadmap'!$O$2:$O$21,MATCH($A6,'Performance & Roadmap'!$A$2:$A$21,0)) -> 2026-10-20 | AM6: =INDEX('Performance & Roadmap'!$Q$2:$Q$21,MATCH($A6,'Performance & Roadmap'!$A$2:$A$21,0)) -> 2026-12-31 | AN6: High | AO6: CMDB; IAM/SSO; contracts; service desk; scans; integration catalog — all synthetic | AP6: Real product; synthetic organization data
A7: APP-006 | B7: Zoom Workplace | C7: Zoom | D7: AI-enabled collaboration suite for meetings, chat, phone, whiteboards, documents, and hybrid work experiences. | E7: Zoom Communications, Inc. | F7: Collaboration | G7: SaaS | H7: Commercial SaaS | I7: Vendor-managed SaaS | J7: Web, desktop, mobile, and room systems | K7: Vendor proprietary; SDKs, APIs, and webhooks | L7: Virtual Care and Digital Workplace | M7: Monica Reed (synthetic) | N7: VP, Virtual Care | O7: monica.reed@northstarhealth.example | P7: Liam Cooper (synthetic) | Q7: Unified Communications Architect | R7: liam.cooper@northstarhealth.example | S7: https://www.zoom.com/en/products/collaboration-tools/ | T7: https://support.zoom.com/ | U7: Virtual meetings and telehealth | V7: No | W7: High | X7: 3 | Y7: Overlaps with Teams, but possible telehealth and room-system dependencies require validation before a decision. | Z7: Internal / possible PHI | AA7: =SUMIF('User Profiles'!$A$2:$A$41,$A7,'User Profiles'!$E$2:$E$41) -> 25500 | AB7: =SUMIF('User Profiles'!$A$2:$A$41,$A7,'User Profiles'!$F$2:$F$41) -> 6620 | AC7: =IFERROR(AB7/AA7,0) -> 0.25960784 | AD7: =SUMIF(TCO!$A$2:$A$21,$A7,TCO!$I$2:$I$21) -> 1130000 | AE7: =SUMIF(TCO!$A$2:$A$21,$A7,TCO!$J$2:$J$21) -> 550000 | AF7: High | AG7: =COUNTIF(Dependencies!$B$2:$B$33,$A7) -> 2 | AH7: =INDEX('Performance & Roadmap'!$C$2:$C$21,MATCH($A7,'Performance & Roadmap'!$A$2:$A$21,0)) -> 0.9994 | AI7: =INDEX('Performance & Roadmap'!$D$2:$D$21,MATCH($A7,'Performance & Roadmap'!$A$2:$A$21,0)) -> 0.999 | AJ7: =INDEX('Performance & Roadmap'!$K$2:$K$21,MATCH($A7,'Performance & Roadmap'!$A$2:$A$21,0)) -> Below | AK7: =INDEX('Performance & Roadmap'!$M$2:$M$21,MATCH($A7,'Performance & Roadmap'!$A$2:$A$21,0)) -> Review | AL7: =INDEX('Performance & Roadmap'!$O$2:$O$21,MATCH($A7,'Performance & Roadmap'!$A$2:$A$21,0)) -> 2026-09-25 | AM7: =INDEX('Performance & Roadmap'!$Q$2:$Q$21,MATCH($A7,'Performance & Roadmap'!$A$2:$A$21,0)) -> 2026-11-30 | AN7: Low | AO7: CMDB; IAM/SSO; contracts; service desk; scans; integration catalog — all synthetic | AP7: Real product; synthetic organization data
A8: APP-007 | B8: Microsoft Dragon Copilot | C8: Dragon Copilot | D8: Clinical AI assistant combining ambient conversation capture, clinical note generation, dictation, and workflow assistance. | E8: Microsoft Corporation | F8: Clinical AI | G8: AI Tool / Agent | H8: Commercial SaaS | I8: Vendor-managed SaaS | J8: Web, desktop, and mobile with EHR integration | K8: Vendor proprietary AI; EHR connectors and APIs | L8: Clinical Transformation | M8: Daniel Kim (synthetic) | N8: Chief Clinical Transformation Officer | O8: daniel.kim@northstarhealth.example | P8: Aisha Grant (synthetic) | Q8: Clinical AI Architect | R8: aisha.grant@northstarhealth.example | S8: https://www.microsoft.com/en-us/health-solutions/clinical-workflow/dragon-copilot | T8: https://support.microsoft.com/en-US/dragon-copilot/physicians/welcome-to-microsoft-dragon-copilot | U8: Ambient clinical documentation | V8: No | W8: High | X8: 5 | Y8: Strategic clinical AI standard with broad specialty coverage, strong adoption, and integration across core EHR workflows. | Z8: PHI | AA8: =SUMIF('User Profiles'!$A$2:$A$41,$A8,'User Profiles'!$E$2:$E$41) -> 3700 | AB8: =SUMIF('User Profiles'!$A$2:$A$41,$A8,'User Profiles'!$F$2:$F$41) -> 3180 | AC8: =IFERROR(AB8/AA8,0) -> 0.85945946 | AD8: =SUMIF(TCO!$A$2:$A$21,$A8,TCO!$I$2:$I$21) -> 1670000 | AE8: =SUMIF(TCO!$A$2:$A$21,$A8,TCO!$J$2:$J$21) -> 0 | AF8: High | AG8: =COUNTIF(Dependencies!$B$2:$B$33,$A8) -> 2 | AH8: =INDEX('Performance & Roadmap'!$C$2:$C$21,MATCH($A8,'Performance & Roadmap'!$A$2:$A$21,0)) -> 0.9991 | AI8: =INDEX('Performance & Roadmap'!$D$2:$D$21,MATCH($A8,'Performance & Roadmap'!$A$2:$A$21,0)) -> 0.995 | AJ8: =INDEX('Performance & Roadmap'!$K$2:$K$21,MATCH($A8,'Performance & Roadmap'!$A$2:$A$21,0)) -> Meets | AK8: =INDEX('Performance & Roadmap'!$M$2:$M$21,MATCH($A8,'Performance & Roadmap'!$A$2:$A$21,0)) -> Strategic Invest | AL8: =INDEX('Performance & Roadmap'!$O$2:$O$21,MATCH($A8,'Performance & Roadmap'!$A$2:$A$21,0)) -> 2027-01-15 | AM8: =INDEX('Performance & Roadmap'!$Q$2:$Q$21,MATCH($A8,'Performance & Roadmap'!$A$2:$A$21,0)) -> 2027-02-28 | AN8: High | AO8: CMDB; IAM/SSO; contracts; service desk; scans; integration catalog — all synthetic | AP8: Real product; synthetic organization data
A9: APP-008 | B9: Abridge | C9: Abridge | D9: Generative AI platform that captures clinical conversations and drafts clinically useful notes inside EHR workflows. | E9: Abridge AI, Inc. | F9: Clinical AI | G9: AI Tool / Agent | H9: Commercial SaaS | I9: Vendor-managed SaaS | J9: Mobile and web with EHR integration | K9: Vendor proprietary AI; EHR connectors and APIs | L9: Clinical Transformation | M9: Daniel Kim (synthetic) | N9: Chief Clinical Transformation Officer | O9: daniel.kim@northstarhealth.example | P9: Aisha Grant (synthetic) | Q9: Clinical AI Architect | R9: aisha.grant@northstarhealth.example | S9: https://www.abridge.com/product | T9: https://www.abridge.com/contact | U9: Ambient clinical documentation | V9: No | W9: High | X9: 4 | Y9: Provides valuable ambient documentation but overlaps the selected strategic clinical AI platform for most enrolled specialties. | Z9: PHI | AA9: =SUMIF('User Profiles'!$A$2:$A$41,$A9,'User Profiles'!$E$2:$E$41) -> 2300 | AB9: =SUMIF('User Profiles'!$A$2:$A$41,$A9,'User Profiles'!$F$2:$F$41) -> 975 | AC9: =IFERROR(AB9/AA9,0) -> 0.42391304 | AD9: =SUMIF(TCO!$A$2:$A$21,$A9,TCO!$I$2:$I$21) -> 740000 | AE9: =SUMIF(TCO!$A$2:$A$21,$A9,TCO!$J$2:$J$21) -> 380000 | AF9: High | AG9: =COUNTIF(Dependencies!$B$2:$B$33,$A9) -> 1 | AH9: =INDEX('Performance & Roadmap'!$C$2:$C$21,MATCH($A9,'Performance & Roadmap'!$A$2:$A$21,0)) -> 0.9978 | AI9: =INDEX('Performance & Roadmap'!$D$2:$D$21,MATCH($A9,'Performance & Roadmap'!$A$2:$A$21,0)) -> 0.995 | AJ9: =INDEX('Performance & Roadmap'!$K$2:$K$21,MATCH($A9,'Performance & Roadmap'!$A$2:$A$21,0)) -> Below | AK9: =INDEX('Performance & Roadmap'!$M$2:$M$21,MATCH($A9,'Performance & Roadmap'!$A$2:$A$21,0)) -> Consolidation Candidate | AL9: =INDEX('Performance & Roadmap'!$O$2:$O$21,MATCH($A9,'Performance & Roadmap'!$A$2:$A$21,0)) -> 2026-11-10 | AM9: =INDEX('Performance & Roadmap'!$Q$2:$Q$21,MATCH($A9,'Performance & Roadmap'!$A$2:$A$21,0)) -> 2026-12-15 | AN9: High | AO9: CMDB; IAM/SSO; contracts; service desk; scans; integration catalog — all synthetic | AP9: Real product; synthetic organization data
A10: APP-009 | B10: Nabla Copilot | C10: Nabla | D10: Ambient clinical AI assistant that generates clinical documentation from patient-clinician conversations. | E10: Nabla | F10: Clinical AI | G10: AI Tool / Agent | H10: Commercial SaaS | I10: Vendor-managed SaaS | J10: Web and mobile with EHR integration | K10: Vendor proprietary AI; EHR connectors and APIs | L10: Clinical Transformation | M10: Daniel Kim (synthetic) | N10: Chief Clinical Transformation Officer | O10: daniel.kim@northstarhealth.example | P10: Aisha Grant (synthetic) | Q10: Clinical AI Architect | R10: aisha.grant@northstarhealth.example | S10: https://www.nabla.com/ | T10: https://www.nabla.com/contact | U10: Ambient clinical documentation | V10: No | W10: Low | X10: 2 | Y10: Small pilot with low utilization and no validated unique capability beyond the enterprise clinical AI standard. | Z10: PHI | AA10: =SUMIF('User Profiles'!$A$2:$A$41,$A10,'User Profiles'!$E$2:$E$41) -> 1250 | AB10: =SUMIF('User Profiles'!$A$2:$A$41,$A10,'User Profiles'!$F$2:$F$41) -> 170 | AC10: =IFERROR(AB10/AA10,0) -> 0.136 | AD10: =SUMIF(TCO!$A$2:$A$21,$A10,TCO!$I$2:$I$21) -> 400000 | AE10: =SUMIF(TCO!$A$2:$A$21,$A10,TCO!$J$2:$J$21) -> 240000 | AF10: High | AG10: =COUNTIF(Dependencies!$B$2:$B$33,$A10) -> 1 | AH10: =INDEX('Performance & Roadmap'!$C$2:$C$21,MATCH($A10,'Performance & Roadmap'!$A$2:$A$21,0)) -> 0.996 | AI10: =INDEX('Performance & Roadmap'!$D$2:$D$21,MATCH($A10,'Performance & Roadmap'!$A$2:$A$21,0)) -> 0.995 | AJ10: =INDEX('Performance & Roadmap'!$K$2:$K$21,MATCH($A10,'Performance & Roadmap'!$A$2:$A$21,0)) -> Below | AK10: =INDEX('Performance & Roadmap'!$M$2:$M$21,MATCH($A10,'Performance & Roadmap'!$A$2:$A$21,0)) -> Pilot / Exit Candidate | AL10: =INDEX('Performance & Roadmap'!$O$2:$O$21,MATCH($A10,'Performance & Roadmap'!$A$2:$A$21,0)) -> 2026-12-01 | AM10: =INDEX('Performance & Roadmap'!$Q$2:$Q$21,MATCH($A10,'Performance & Roadmap'!$A$2:$A$21,0)) -> 2026-10-31 | AN10: High | AO10: CMDB; IAM/SSO; contracts; service desk; scans; integration catalog — all synthetic | AP10: Real product; synthetic organization data
A11: APP-010 | B11: Suki Assistant | C11: Suki | D11: Healthcare AI assistant for ambient clinical notes, dictation, coding support, and other clinician administrative tasks. | E11: Suki AI, Inc. | F11: Clinical AI | G11: AI Tool / Agent | H11: Commercial SaaS | I11: Vendor-managed SaaS | J11: Web and mobile with EHR integration | K11: Vendor proprietary AI; EHR connectors and APIs | L11: Clinical Transformation | M11: Daniel Kim (synthetic) | N11: Chief Clinical Transformation Officer | O11: daniel.kim@northstarhealth.example | P11: Aisha Grant (synthetic) | Q11: Clinical AI Architect | R11: aisha.grant@northstarhealth.example | S11: https://www.suki.ai/ | T11: https://www.suki.ai/contact | U11: Ambient clinical documentation | V11: No | W11: High | X11: 3 | Y11: Useful in selected specialties but materially overlaps Dragon Copilot; migration feasibility is considered acceptable in this test scenario. | Z11: PHI | AA11: =SUMIF('User Profiles'!$A$2:$A$41,$A11,'User Profiles'!$E$2:$E$41) -> 1860 | AB11: =SUMIF('User Profiles'!$A$2:$A$41,$A11,'User Profiles'!$F$2:$F$41) -> 645 | AC11: =IFERROR(AB11/AA11,0) -> 0.34677419 | AD11: =SUMIF(TCO!$A$2:$A$21,$A11,TCO!$I$2:$I$21) -> 620000 | AE11: =SUMIF(TCO!$A$2:$A$21,$A11,TCO!$J$2:$J$21) -> 300000 | AF11: High | AG11: =COUNTIF(Dependencies!$B$2:$B$33,$A11) -> 2 | AH11: =INDEX('Performance & Roadmap'!$C$2:$C$21,MATCH($A11,'Performance & Roadmap'!$A$2:$A$21,0)) -> 0.998 | AI11: =INDEX('Performance & Roadmap'!$D$2:$D$21,MATCH($A11,'Performance & Roadmap'!$A$2:$A$21,0)) -> 0.995 | AJ11: =INDEX('Performance & Roadmap'!$K$2:$K$21,MATCH($A11,'Performance & Roadmap'!$A$2:$A$21,0)) -> Below | AK11: =INDEX('Performance & Roadmap'!$M$2:$M$21,MATCH($A11,'Performance & Roadmap'!$A$2:$A$21,0)) -> Consolidation Candidate | AL11: =INDEX('Performance & Roadmap'!$O$2:$O$21,MATCH($A11,'Performance & Roadmap'!$A$2:$A$21,0)) -> 2026-11-20 | AM11: =INDEX('Performance & Roadmap'!$Q$2:$Q$21,MATCH($A11,'Performance & Roadmap'!$A$2:$A$21,0)) -> 2027-01-15 | AN11: High | AO11: CMDB; IAM/SSO; contracts; service desk; scans; integration catalog — all synthetic | AP11: Real product; synthetic organization data
A12: APP-011 | B12: QGenda ProviderCloud | C12: QGenda | D12: Healthcare provider operations platform supporting provider scheduling, credentialing, time tracking, compensation, capacity, and workforce analytics. | E12: QGenda, LLC | F12: Workforce Management | G12: SaaS | H12: Commercial SaaS | I12: Vendor-managed SaaS | J12: Web and mobile | K12: Vendor proprietary; APIs and file-based integrations | L12: Provider Operations | M12: Jordan Brooks (synthetic) | N12: VP, Provider Operations | O12: jordan.brooks@northstarhealth.example | P12: Olivia Price (synthetic) | Q12: Provider Scheduling Lead | R12: olivia.price@northstarhealth.example | S12: https://www.qgenda.com/ | T12: https://www.qgenda.com/contact-us/ | U12: Provider scheduling | V12: Yes | W12: Critical | X12: 5 | Y12: Primary provider scheduling and on-call platform with high adoption and direct linkage to staffing and patient access. | Z12: PII / Workforce | AA12: =SUMIF('User Profiles'!$A$2:$A$41,$A12,'User Profiles'!$E$2:$E$41) -> 12500 | AB12: =SUMIF('User Profiles'!$A$2:$A$41,$A12,'User Profiles'!$F$2:$F$41) -> 11480 | AC12: =IFERROR(AB12/AA12,0) -> 0.9184 | AD12: =SUMIF(TCO!$A$2:$A$21,$A12,TCO!$I$2:$I$21) -> 1190000 | AE12: =SUMIF(TCO!$A$2:$A$21,$A12,TCO!$J$2:$J$21) -> 0 | AF12: Medium | AG12: =COUNTIF(Dependencies!$B$2:$B$33,$A12) -> 2 | AH12: =INDEX('Performance & Roadmap'!$C$2:$C$21,MATCH($A12,'Performance & Roadmap'!$A$2:$A$21,0)) -> 0.9992 | AI12: =INDEX('Performance & Roadmap'!$D$2:$D$21,MATCH($A12,'Performance & Roadmap'!$A$2:$A$21,0)) -> 0.999 | AJ12: =INDEX('Performance & Roadmap'!$K$2:$K$21,MATCH($A12,'Performance & Roadmap'!$A$2:$A$21,0)) -> Meets | AK12: =INDEX('Performance & Roadmap'!$M$2:$M$21,MATCH($A12,'Performance & Roadmap'!$A$2:$A$21,0)) -> Active | AL12: =INDEX('Performance & Roadmap'!$O$2:$O$21,MATCH($A12,'Performance & Roadmap'!$A$2:$A$21,0)) -> 2027-02-20 | AM12: =INDEX('Performance & Roadmap'!$Q$2:$Q$21,MATCH($A12,'Performance & Roadmap'!$A$2:$A$21,0)) -> 2027-04-30 | AN12: High | AO12: CMDB; IAM/SSO; contracts; service desk; scans; integration catalog — all synthetic | AP12: Real product; synthetic organization data
A13: APP-012 | B13: UKG Pro Workforce Management | C13: UKG WFM | D13: Workforce management suite for time and attendance, scheduling, labor analytics, compliance, and frontline workforce operations. | E13: UKG, Inc. | F13: Workforce Management | G13: SaaS | H13: Commercial SaaS | I13: Vendor-managed SaaS | J13: Web, mobile, and time-clock endpoints | K13: Vendor proprietary; APIs and integration tooling | L13: Workforce Operations | M13: Carla Nguyen (synthetic) | N13: VP, Workforce Operations | O13: carla.nguyen@northstarhealth.example | P13: Henry Adams (synthetic) | Q13: Workforce Management Solution Architect | R13: henry.adams@northstarhealth.example | S13: https://www.ukg.com/products/ukg-pro-workforce-management | T13: https://www.ukg.com/support | U13: Time and attendance | V13: Yes | W13: High | X13: 4 | Y13: Enterprise standard for timekeeping and frontline scheduling; complements rather than duplicates provider-specific QGenda workflows. | Z13: PII / Workforce | AA13: =SUMIF('User Profiles'!$A$2:$A$41,$A13,'User Profiles'!$E$2:$E$41) -> 39000 | AB13: =SUMIF('User Profiles'!$A$2:$A$41,$A13,'User Profiles'!$F$2:$F$41) -> 32950 | AC13: =IFERROR(AB13/AA13,0) -> 0.84487179 | AD13: =SUMIF(TCO!$A$2:$A$21,$A13,TCO!$I$2:$I$21) -> 1460000 | AE13: =SUMIF(TCO!$A$2:$A$21,$A13,TCO!$J$2:$J$21) -> 0 | AF13: Medium | AG13: =COUNTIF(Dependencies!$B$2:$B$33,$A13) -> 1 | AH13: =INDEX('Performance & Roadmap'!$C$2:$C$21,MATCH($A13,'Performance & Roadmap'!$A$2:$A$21,0)) -> 0.999 | AI13: =INDEX('Performance & Roadmap'!$D$2:$D$21,MATCH($A13,'Performance & Roadmap'!$A$2:$A$21,0)) -> 0.999 | AJ13: =INDEX('Performance & Roadmap'!$K$2:$K$21,MATCH($A13,'Performance & Roadmap'!$A$2:$A$21,0)) -> Below | AK13: =INDEX('Performance & Roadmap'!$M$2:$M$21,MATCH($A13,'Performance & Roadmap'!$A$2:$A$21,0)) -> Active | AL13: =INDEX('Performance & Roadmap'!$O$2:$O$21,MATCH($A13,'Performance & Roadmap'!$A$2:$A$21,0)) -> 2026-11-12 | AM13: =INDEX('Performance & Roadmap'!$Q$2:$Q$21,MATCH($A13,'Performance & Roadmap'!$A$2:$A$21,0)) -> 2027-05-31 | AN13: High | AO13: CMDB; IAM/SSO; contracts; service desk; scans; integration catalog — all synthetic | AP13: Real product; synthetic organization data
... A21: APP-020 | B21: Imprivata Enterprise Access Management | C21: Imprivata EAM | D21: Healthcare access management platform providing single sign-on, multifactor and passwordless authentication, badge access, and shared-workstation workflows. | E21: Imprivata, Inc. | F21: Access Management | G21: Application Platform | H21: Commercial off-the-shelf | I21: Hybrid: on-premises connectors with vendor cloud services (synthetic deployment) | J21: Windows endpoints, virtual desktops, web applications, and identity integrations | K21: Vendor proprietary; connectors, policies, and APIs | L21: Cybersecurity and Clinical Technology | M21: Marcus Lee (synthetic) | N21: Chief Information Security Officer | O21: marcus.lee@northstarhealth.example | P21: Owen Scott (synthetic) | Q21: Clinical Access Management Architect | R21: owen.scott@northstarhealth.example | S21: https://www.imprivata.com/products/access-management/enterprise-access-management | T21: https://www.imprivata.com/support | U21: Clinical identity and access management | V21: Yes | W21: Critical | X21: 5 | Y21: Enables rapid secure access to critical clinical systems and shared workstations; high downstream dependency count. | Z21: Security / Identity | AA21: =SUMIF('User Profiles'!$A$2:$A$41,$A21,'User Profiles'!$E$2:$E$41) -> 32300 | AB21: =SUMIF('User Profiles'!$A$2:$A$41,$A21,'User Profiles'!$F$2:$F$41) -> 30290 | AC21: =IFERROR(AB21/AA21,0) -> 0.9377709 | AD21: =SUMIF(TCO!$A$2:$A$21,$A21,TCO!$I$2:$I$21) -> 1560000 | AE21: =SUMIF(TCO!$A$2:$A$21,$A21,TCO!$J$2:$J$21) -> 0 | AF21: High | AG21: =COUNTIF(Dependencies!$B$2:$B$33,$A21) -> 2 | AH21: =INDEX('Performance & Roadmap'!$C$2:$C$21,MATCH($A21,'Performance & Roadmap'!$A$2:$A$21,0)) -> 0.9999 | AI21: =INDEX('Performance & Roadmap'!$D$2:$D$21,MATCH($A21,'Performance & Roadmap'!$A$2:$A$21,0)) -> 0.999 | AJ21: =INDEX('Performance & Roadmap'!$K$2:$K$21,MATCH($A21,'Performance & Roadmap'!$A$2:$A$21,0)) -> Meets | AK21: =INDEX('Performance & Roadmap'!$M$2:$M$21,MATCH($A21,'Performance & Roadmap'!$A$2:$A$21,0)) -> Strategic Invest | AL21: =INDEX('Performance & Roadmap'!$O$2:$O$21,MATCH($A21,'Performance & Roadmap'!$A$2:$A$21,0)) -> 2027-02-10 | AM21: =INDEX('Performance & Roadmap'!$Q$2:$Q$21,MATCH($A21,'Performance & Roadmap'!$A$2:$A$21,0)) -> 2027-05-31 | AN21: High | AO21: CMDB; IAM/SSO; contracts; service desk; scans; integration catalog — all synthetic | AP21: Real product; synthetic organization data

Sheet User Profiles
A1: App ID | B1: Application Name | C1: User Population | D1: Access Level | E1: Entitled Users | F1: Active Users (90d) | G1: Inactive Users (90d) | H1: Avg Weekly Sessions / Active User | I1: Avg Monthly Transactions | J1: Region | K1: Evidence Source | L1: Evidence Confidence
A2: APP-001 | B2: Epic | C2: Platform administrators and super users | D2: Power user | E2: 4500 | F2: 4200 | G2: =E2-F2 -> 300 | H2: 18 | I2: 672000 | J2: Global | K2: IAM / SSO telemetry; license export; synthetic values | L2: High
A3: APP-001 | B3: Epic | C3: Business and clinical end users | D3: Regular user | E3: 28000 | F3: 25200 | G3: =E3-F3 -> 2800 | H3: 10 | I3: 2620800 | J3: Global | K3: IAM / SSO telemetry; license export; synthetic values | L3: High
A4: APP-002 | B4: Oracle Health EHR | C4: Platform administrators and super users | D4: Power user | E4: 1200 | F4: 900 | G4: =E4-F4 -> 300 | H4: 14 | I4: 108000 | J4: Global | K4: IAM / SSO telemetry; license export; synthetic values | L4: High
A5: APP-002 | B5: Oracle Health EHR | C5: Business and clinical end users | D5: Regular user | E5: 9000 | F5: 6300 | G5: =E5-F5 -> 2700 | H5: 8 | I5: 491400 | J5: Global | K5: IAM / SSO telemetry; license export; synthetic values | L5: High
A6: APP-003 | B6: athenaOne | C6: Platform administrators and super users | D6: Power user | E6: 300 | F6: 260 | G6: =E6-F6 -> 40 | H6: 12 | I6: 24700 | J6: Global | K6: IAM / SSO telemetry; license export; synthetic values | L6: High
A7: APP-003 | B7: athenaOne | C7: Business and clinical end users | D7: Regular user | E7: 2700 | F7: 2300 | G7: =E7-F7 -> 400 | H7: 7 | I7: 142025 | J7: Global | K7: IAM / SSO telemetry; license export; synthetic values | L7: High
A8: APP-004 | B8: Microsoft Teams Enterprise | C8: Platform administrators and super users | D8: Power user | E8: 1500 | F8: 1400 | G8: =E8-F8 -> 100 | H8: 20 | I8: 182000 | J8: Global | K8: IAM / SSO telemetry; license export; synthetic values | L8: High
A9: APP-004 | B9: Microsoft Teams Enterprise | C9: Business and clinical end users | D9: Regular user | E9: 40000 | F9: 33000 | G9: =E9-F9 -> 7000 | H9: 11 | I9: 2788500 | J9: Global | K9: IAM / SSO telemetry; license export; synthetic values | L9: High
A10: APP-005 | B10: Slack Enterprise Grid | C10: Platform administrators and super users | D10: Power user | E10: 800 | F10: 620 | G10: =E10-F10 -> 180 | H10: 17 | I10: 55800 | J10: Global | K10: IAM / SSO telemetry; license export; synthetic values | L10: High
A11: APP-005 | B11: Slack Enterprise Grid | C11: Business and clinical end users | D11: Regular user | E11: 10000 | F11: 4700 | G11: =E11-F11 -> 5300 | H11: 9 | I11: 274950 | J11: Global | K11: IAM / SSO telemetry; license export; synthetic values | L11: High
A12: APP-006 | B12: Zoom Workplace | C12: Platform administrators and super users | D12: Power user | E12: 500 | F12: 420 | G12: =E12-F12 -> 80 | H12: 10 | I12: 23100 | J12: Global | K12: IAM / SSO telemetry; license export; synthetic values | L12: Low
A13: APP-006 | B13: Zoom Workplace | C13: Business and clinical end users | D13: Regular user | E13: 25000 | F13: 6200 | G13: =E13-F13 -> 18800 | H13: 6 | I13: 221650 | J13: Global | K13: IAM / SSO telemetry; license export; synthetic values | L13: Low
... A41: APP-020 | B41: Imprivata Enterprise Access Management | C41: Business and clinical end users | D41: Regular user | E41: 32000 | F41: 30000 | G41: =E41-F41 -> 2000 | H41: 17 | I41: 3510000 | J41: Global | K41: IAM / SSO telemetry; license export; synthetic values | L41: High

Sheet Capability Map
A1: App ID | B1: Application Name | C1: Capability ID | D1: Capability | E1: Process / Tasks Enabled | F1: Support Role | G1: Coverage Level | H1: Capability Criticality | I1: Critical Operation Flag | J1: Evidence Source | K1: Evidence Confidence | L1: Data Status
A2: APP-001 | B2: Epic | C2: CAP-001 | D2: Patient record management | E2: Maintain longitudinal patient chart, results, medications, and encounter history | F2: Primary | G2: Full | H2: Critical | I2: Yes | J2: Product documentation; process taxonomy; synthetic mapping | K2: High | L2: Synthetic organization mapping
A3: APP-001 | B3: Epic | C3: CAP-002 | D3: Clinical documentation | E3: Create, review, sign, and retrieve clinical notes | F3: Primary | G3: Full | H3: Critical | I3: Yes | J3: Product documentation; process taxonomy; synthetic mapping | K3: High | L3: Synthetic organization mapping
A4: APP-001 | B4: Epic | C4: CAP-003 | D4: Clinical order management | E4: Enter, route, verify, and track orders | F4: Primary | G4: Full | H4: Critical | I4: Yes | J4: Product documentation; process taxonomy; synthetic mapping | K4: High | L4: Synthetic organization mapping
A5: APP-001 | B5: Epic | C5: CAP-004 | D5: Revenue cycle operations | E5: Capture charges, code encounters, and support billing workflows | F5: Secondary | G5: Full | H5: High | I5: Yes | J5: Product documentation; process taxonomy; synthetic mapping | K5: High | L5: Synthetic organization mapping
A6: APP-002 | B6: Oracle Health EHR | C6: CAP-001 | D6: Patient record management | E6: Maintain patient chart and clinical history at acquired hospitals | F6: Duplicative | G6: Full | H6: Critical | I6: Yes | J6: Product documentation; process taxonomy; synthetic mapping | K6: High | L6: Synthetic organization mapping
A7: APP-002 | B7: Oracle Health EHR | C7: CAP-002 | D7: Clinical documentation | E7: Create and sign clinical notes | F7: Duplicative | G7: Full | H7: Critical | I7: Yes | J7: Product documentation; process taxonomy; synthetic mapping | K7: High | L7: Synthetic organization mapping
A8: APP-002 | B8: Oracle Health EHR | C8: CAP-003 | D8: Clinical order management | E8: Enter and manage orders | F8: Duplicative | G8: Full | H8: Critical | I8: Yes | J8: Product documentation; process taxonomy; synthetic mapping | K8: High | L8: Synthetic organization mapping
A9: APP-002 | B9: Oracle Health EHR | C9: CAP-005 | D9: Care coordination | E9: Share clinical context and coordinate care teams | F9: Secondary | G9: Partial | H9: High | I9: Yes | J9: Product documentation; process taxonomy; synthetic mapping | K9: High | L9: Synthetic organization mapping
A10: APP-003 | B10: athenaOne | C10: CAP-006 | D10: Ambulatory care delivery | E10: Support outpatient encounters, specialty workflows, and patient charts | F10: Primary | G10: Full | H10: High | I10: Yes | J10: Product documentation; process taxonomy; synthetic mapping | K10: High | L10: Synthetic organization mapping
A11: APP-003 | B11: athenaOne | C11: CAP-004 | D11: Revenue cycle operations | E11: Submit claims, manage billing, and track collections | F11: Primary | G11: Full | H11: High | I11: Yes | J11: Product documentation; process taxonomy; synthetic mapping | K11: High | L11: Synthetic organization mapping
A12: APP-003 | B12: athenaOne | C12: CAP-007 | D12: Patient engagement | E12: Provide portal, messaging, reminders, payments, and telehealth | F12: Primary | G12: Full | H12: High | I12: No | J12: Product documentation; process taxonomy; synthetic mapping | K12: High | L12: Synthetic organization mapping
... A58: APP-020 | B58: Imprivata Enterprise Access Management | C58: CAP-032 | D58: Access security analytics | E58: Monitor authentication patterns and policy compliance | F58: Primary | G58: Full | H58: High | I58: No | J58: Product documentation; process taxonomy; synthetic mapping | K58: High | L58: Synthetic organization mapping

Sheet Risks
A1: Risk ID | B1: App ID | C1: Application Name | D1: Risk Category | E1: Risk Description | F1: Severity Score (1-5) | G1: Likelihood Score (1-5) | H1: Inherent Risk Score | I1: Risk Level | J1: Mitigation Plan | K1: Mitigation Owner | L1: Status | M1: Mitigation Due Date | N1: Residual Risk | O1: Evidence Source | P1: Data Status
A2: RISK-001 | B2: APP-001 | C2: Epic | D2: Security | E2: Concentration of PHI and privileged clinical access creates high breach impact. | F2: 5 | G2: 3 | H2: =F2*G2 -> 15 | I2: =IF(H2>=20,"Critical",IF(H2>=12,"High",IF(H2>=6,"Medium","Low"))) -> High | J2: Enforce MFA, privileged-access reviews, segmentation, and quarterly access recertification. | K2: Cybersecurity | L2: Mitigating | M2: 2026-12-15 | N2: High | O2: Security scan / BCP record / service desk evidence; synthetic assessment | P2: Synthetic organization risk
A3: RISK-002 | B3: APP-001 | C3: Epic | D3: Business Continuity | E3: An extended EHR outage would disrupt documentation, orders, and patient flow. | F3: 5 | G3: 2 | H3: =F3*G3 -> 10 | I3: =IF(H3>=20,"Critical",IF(H3>=12,"High",IF(H3>=6,"Medium","Low"))) -> Medium | J3: Maintain tested downtime workflows, redundant hosting, and semiannual disaster recovery exercises. | K3: Clinical Technology | L3: Mitigating | M3: 2026-11-30 | N3: Medium | O3: Security scan / BCP record / service desk evidence; synthetic assessment | P3: Synthetic organization risk
A4: RISK-003 | B4: APP-002 | C4: Oracle Health EHR | D4: Technical | E4: Extensive local customizations increase upgrade effort and migration complexity. | F4: 4 | G4: 4 | H4: =F4*G4 -> 16 | I4: =IF(H4>=20,"Critical",IF(H4>=12,"High",IF(H4>=6,"Medium","Low"))) -> High | J4: Inventory customizations, retire unused extensions, and map required workflows to the target EHR. | K4: Clinical Informatics | L4: Open | M4: 2026-10-31 | N4: High | O4: Security scan / BCP record / service desk evidence; synthetic assessment | P4: Synthetic organization risk
A5: RISK-004 | B5: APP-002 | C5: Oracle Health EHR | D5: Business Continuity | E5: Interface instability can delay orders and results at acquired hospitals. | F5: 5 | G5: 3 | H5: =F5*G5 -> 15 | I5: =IF(H5>=20,"Critical",IF(H5>=12,"High",IF(H5>=6,"Medium","Low"))) -> High | J5: Prioritize interface monitoring, reconciliation, and staged migration with rollback plans. | K5: Integration Services | L5: Mitigating | M5: 2026-11-15 | N5: High | O5: Security scan / BCP record / service desk evidence; synthetic assessment | P5: Synthetic organization risk
A6: RISK-005 | B6: APP-003 | C6: athenaOne | D6: Vendor | E6: Collections-based commercial model and vendor dependency may constrain cost predictability. | F6: 3 | G6: 3 | H6: =F6*G6 -> 9 | I6: =IF(H6>=20,"Critical",IF(H6>=12,"High",IF(H6>=6,"Medium","Low"))) -> Medium | J6: Model volume sensitivity and confirm exit/data portability terms before renewal. | K6: Ambulatory Operations | L6: Open | M6: 2026-12-01 | N6: Medium | O6: Security scan / BCP record / service desk evidence; synthetic assessment | P6: Synthetic organization risk
A7: RISK-006 | B7: APP-003 | C7: athenaOne | D7: Security | E7: Cloud EHR stores PHI and requires strong access and third-party risk controls. | F7: 4 | G7: 2 | H7: =F7*G7 -> 8 | I7: =IF(H7>=20,"Critical",IF(H7>=12,"High",IF(H7>=6,"Medium","Low"))) -> Medium | J7: Complete annual vendor security review and enforce SSO/MFA and role-based access. | K7: Cybersecurity | L7: Mitigating | M7: 2026-10-15 | N7: Medium | O7: Security scan / BCP record / service desk evidence; synthetic assessment | P7: Synthetic organization risk
A8: RISK-007 | B8: APP-004 | C8: Microsoft Teams Enterprise | D8: Security | E8: Broad collaboration and external sharing can expose sensitive information. | F8: 4 | G8: 3 | H8: =F8*G8 -> 12 | I8: =IF(H8>=20,"Critical",IF(H8>=12,"High",IF(H8>=6,"Medium","Low"))) -> High | J8: Apply sensitivity labels, DLP, external-sharing controls, and retention policies. | K8: Cybersecurity | L8: Mitigating | M8: 2026-10-31 | N8: Medium | O8: Security scan / BCP record / service desk evidence; synthetic assessment | P8: Synthetic organization risk
A9: RISK-008 | B9: APP-004 | C9: Microsoft Teams Enterprise | D9: Operational | E9: Tenant-wide service disruption would affect enterprise communications. | F9: 4 | G9: 2 | H9: =F9*G9 -> 8 | I9: =IF(H9>=20,"Critical",IF(H9>=12,"High",IF(H9>=6,"Medium","Low"))) -> Medium | J9: Maintain outage communications channels and documented fallback procedures. | K9: Digital Workplace | L9: Accepted | M9: 2026-12-31 | N9: Low | O9: Security scan / BCP record / service desk evidence; synthetic assessment | P9: Synthetic organization risk
A10: RISK-009 | B10: APP-005 | C10: Slack Enterprise Grid | D10: Regulatory | E10: Unmanaged channels and retention settings can create PHI and eDiscovery exposure. | F10: 4 | G10: 4 | H10: =F10*G10 -> 16 | I10: =IF(H10>=20,"Critical",IF(H10>=12,"High",IF(H10>=6,"Medium","Low"))) -> High | J10: Restrict PHI use, enforce enterprise retention, archive required content, and review apps. | K10: Legal and Cybersecurity | L10: Open | M10: 2026-10-15 | N10: High | O10: Security scan / BCP record / service desk evidence; synthetic assessment | P10: Synthetic organization risk
A11: RISK-010 | B11: APP-005 | C11: Slack Enterprise Grid | D11: Technical | E11: Fourteen workflow integrations create migration and retirement complexity. | F11: 3 | G11: 4 | H11: =F11*G11 -> 12 | I11: =IF(H11>=20,"Critical",IF(H11>=12,"High",IF(H11>=6,"Medium","Low"))) -> High | J11: Inventory integrations and migrate required workflows to Teams or ServiceNow. | K11: Digital Workplace | L11: Open | M11: 2026-11-30 | N11: Medium | O11: Security scan / BCP record / service desk evidence; synthetic assessment | P11: Synthetic organization risk
A12: RISK-011 | B12: APP-006 | C12: Zoom Workplace | D12: Regulatory | E12: Recorded meetings or telehealth sessions may contain PHI with inconsistent retention. | F12: 5 | G12: 3 | H12: =F12*G12 -> 15 | I12: =IF(H12>=20,"Critical",IF(H12>=12,"High",IF(H12>=6,"Medium","Low"))) -> High | J12: Validate telehealth workflows, disable unnecessary recording, and enforce retention controls. | K12: Virtual Care | L12: Open | M12: 2026-09-30 | N12: High | O12: Security scan / BCP record / service desk evidence; synthetic assessment | P12: Synthetic organization risk
A13: RISK-012 | B13: APP-006 | C13: Zoom Workplace | D13: Dependency | E13: Room systems and external patient workflows may not be fully replaceable by Teams. | F13: 4 | G13: 4 | H13: =F13*G13 -> 16 | I13: =IF(H13>=20,"Critical",IF(H13>=12,"High",IF(H13>=6,"Medium","Low"))) -> High | J13: Complete device, workflow, and contract dependency validation before committing savings. | K13: Unified Communications | L13: Open | M13: 2026-10-15 | N13: High | O13: Security scan / BCP record / service desk evidence; synthetic assessment | P13: Synthetic organization risk
... A41: RISK-040 | B41: APP-020 | C41: Imprivata Enterprise Access Management | D41: Security | E41: Compromised authentication policy or badge workflow has an enterprise-wide blast radius. | F41: 5 | G41: 3 | H41: =F41*G41 -> 15 | I41: =IF(H41>=20,"Critical",IF(H41>=12,"High",IF(H41>=6,"Medium","Low"))) -> High | J41: Use change control, policy testing, privileged-access monitoring, and rapid rollback. | K41: Cybersecurity | L41: Mitigating | M41: 2026-10-31 | N41: High | O41: Security scan / BCP record / service desk evidence; synthetic assessment | P41: Synthetic organization risk

Sheet TCO
A1: App ID | B1: Application Name | C1: Annual License / Subscription | D1: Annual Maintenance | E1: Annual Infrastructure / Hosting | F1: Annual Vendor Services | G1: Annual Internal Labor | H1: Annual Education / Training | I1: Annual TCO | J1: Avoidable Annual Cost | K1: Avoidable % of TCO | L1: One-Time Transition Cost | M1: First-Year Net Savings | N1: Cost Notes | O1: Evidence Source | P1: Evidence Confidence
A2: APP-001 | B2: Epic | C2: 5200000 | D2: 800000 | E2: 900000 | F2: 400000 | G2: 1300000 | H2: 150000 | I2: =SUM(C2:H2) -> 8750000 | J2: 0 | K2: =IFERROR(J2/I2,0) -> 0 | L2: 0 | M2: =MAX(0,J2-L2) -> 0 | N2: Strategic platform; no committed savings. | O2: Contract ledger; AP spend; labor estimate; synthetic values | P2: High
A3: APP-002 | B3: Oracle Health EHR | C3: 3600000 | D3: 700000 | E3: 800000 | F3: 300000 | G3: 1000000 | H3: 100000 | I3: =SUM(C3:H3) -> 6500000 | J3: 4400000 | K3: =IFERROR(J3/I3,0) -> 0.67692308 | L3: 2200000 | M3: =MAX(0,J3-L3) -> 2200000 | N3: Avoidable after EHR migration, interface cutover, and contract exit. | O3: Contract ledger; AP spend; labor estimate; synthetic values | P3: High
A4: APP-003 | B4: athenaOne | C4: 1000000 | D4: 100000 | E4: 50000 | F4: 120000 | G4: 200000 | H4: 30000 | I4: =SUM(C4:H4) -> 1500000 | J4: 0 | K4: =IFERROR(J4/I4,0) -> 0 | L4: 0 | M4: =MAX(0,J4-L4) -> 0 | N4: Distinct ambulatory operating model. | O4: Contract ledger; AP spend; labor estimate; synthetic values | P4: High
A5: APP-004 | B5: Microsoft Teams Enterprise | C5: 3200000 | D5: 50000 | E5: 50000 | F5: 120000 | G5: 350000 | H5: 60000 | I5: =SUM(C5:H5) -> 3830000 | J5: 0 | K5: =IFERROR(J5/I5,0) -> 0 | L5: 0 | M5: =MAX(0,J5-L5) -> 0 | N5: Strategic collaboration standard. | O5: Contract ledger; AP spend; labor estimate; synthetic values | P5: High
A6: APP-005 | B6: Slack Enterprise Grid | C6: 1000000 | D6: 20000 | E6: 10000 | F6: 50000 | G6: 150000 | H6: 30000 | I6: =SUM(C6:H6) -> 1260000 | J6: 820000 | K6: =IFERROR(J6/I6,0) -> 0.65079365 | L6: 220000 | M6: =MAX(0,J6-L6) -> 600000 | N6: Savings exclude retained archive and migration support. | O6: Contract ledger; AP spend; labor estimate; synthetic values | P6: High
A7: APP-006 | B7: Zoom Workplace | C7: 850000 | D7: 40000 | E7: 20000 | F7: 80000 | G7: 120000 | H7: 20000 | I7: =SUM(C7:H7) -> 1130000 | J7: 550000 | K7: =IFERROR(J7/I7,0) -> 0.48672566 | L7: 180000 | M7: =MAX(0,J7-L7) -> 370000 | N7: Potential only; not safe until telehealth and room dependencies are validated. | O7: Contract ledger; AP spend; labor estimate; synthetic values | P7: Low
A8: APP-007 | B8: Microsoft Dragon Copilot | C8: 1250000 | D8: 50000 | E8: 20000 | F8: 80000 | G8: 220000 | H8: 50000 | I8: =SUM(C8:H8) -> 1670000 | J8: 0 | K8: =IFERROR(J8/I8,0) -> 0 | L8: 0 | M8: =MAX(0,J8-L8) -> 0 | N8: Strategic clinical AI investment. | O8: Contract ledger; AP spend; labor estimate; synthetic values | P8: High
A9: APP-008 | B9: Abridge | C9: 550000 | D9: 20000 | E9: 10000 | F9: 60000 | G9: 80000 | H9: 20000 | I9: =SUM(C9:H9) -> 740000 | J9: 380000 | K9: =IFERROR(J9/I9,0) -> 0.51351351 | L9: 120000 | M9: =MAX(0,J9-L9) -> 260000 | N9: Avoidable after provider and template migration. | O9: Contract ledger; AP spend; labor estimate; synthetic values | P9: High
A10: APP-009 | B10: Nabla Copilot | C10: 300000 | D10: 10000 | E10: 0 | F10: 30000 | G10: 50000 | H10: 10000 | I10: =SUM(C10:H10) -> 400000 | J10: 240000 | K10: =IFERROR(J10/I10,0) -> 0.6 | L10: 30000 | M10: =MAX(0,J10-L10) -> 210000 | N10: Pilot can be exited after data export and vendor offboarding. | O10: Contract ledger; AP spend; labor estimate; synthetic values | P10: High
A11: APP-010 | B11: Suki Assistant | C11: 450000 | D11: 20000 | E11: 10000 | F11: 50000 | G11: 70000 | H11: 20000 | I11: =SUM(C11:H11) -> 620000 | J11: 300000 | K11: =IFERROR(J11/I11,0) -> 0.48387097 | L11: 100000 | M11: =MAX(0,J11-L11) -> 200000 | N11: Avoidable after specialty workflow migration. | O11: Contract ledger; AP spend; labor estimate; synthetic values | P11: High
A12: APP-011 | B12: QGenda ProviderCloud | C12: 850000 | D12: 50000 | E12: 20000 | F12: 90000 | G12: 150000 | H12: 30000 | I12: =SUM(C12:H12) -> 1190000 | J12: 0 | K12: =IFERROR(J12/I12,0) -> 0 | L12: 0 | M12: =MAX(0,J12-L12) -> 0 | N12: Provider operations platform retained. | O12: Contract ledger; AP spend; labor estimate; synthetic values | P12: High
A13: APP-012 | B13: UKG Pro Workforce Management | C13: 950000 | D13: 80000 | E13: 40000 | F13: 100000 | G13: 250000 | H13: 40000 | I13: =SUM(C13:H13) -> 1460000 | J13: 0 | K13: =IFERROR(J13/I13,0) -> 0 | L13: 0 | M13: =MAX(0,J13-L13) -> 0 | N13: Enterprise workforce-management standard. | O13: Contract ledger; AP spend; labor estimate; synthetic values | P13: High
... A21: APP-020 | B21: Imprivata Enterprise Access Management | C21: 900000 | D21: 100000 | E21: 120000 | F21: 80000 | G21: 320000 | H21: 40000 | I21: =SUM(C21:H21) -> 1560000 | J21: 0 | K21: =IFERROR(J21/I21,0) -> 0 | L21: 0 | M21: =MAX(0,J21-L21) -> 0 | N21: Critical enterprise access dependency. | O21: Contract ledger; AP spend; labor estimate; synthetic values | P21: High
A23: Portfolio Annual TCO | I23: =SUM(I2:I21) -> 43250000
A24: Potential Avoidable Annual Cost | J24: =SUM(J2:J21) -> 9390000
A25: Potential First-Year Net Savings | M25: =SUM(M2:M21) -> 5510000

Sheet Dependencies
A1: Dependency ID | B1: Source App ID | C1: Source Application | D1: Target App / System ID | E1: Target Application / System | F1: Dependency Type | G1: Direction | H1: Criticality | I1: Disruption Impact | J1: Data / Service Exchanged | K1: Migration Feasibility | L1: Required Before Disposition | M1: Evidence Source | N1: Evidence Confidence | O1: Data Status
A2: DEP-001 | B2: APP-001 | C2: Epic | D2: APP-020 | E2: Imprivata Enterprise Access Management | F2: Authentication | G2: Consumes | H2: Critical | I2: Clinicians may be unable to access Epic on shared workstations. | J2: Identity assertions and badge authentication | K2: Medium | L2: Maintain break-glass access and failover. | M2: CMDB / interface catalog / synthetic assessment | N2: High | O2: Synthetic organization dependency
A3: DEP-002 | B3: APP-001 | C3: Epic | D3: EXT-001 | E3: Enterprise Integration Engine | F3: Data / Interface | G3: Consumes | H3: Critical | I3: Orders, results, ADT, and downstream feeds may stop. | J3: HL7 and FHIR clinical messages | K3: Low | L3: Cut over and reconcile all interfaces. | M3: CMDB / interface catalog / synthetic assessment | N3: High | O3: Synthetic organization dependency
A4: DEP-003 | B4: APP-001 | C4: Epic | D4: EXT-002 | E4: Enterprise PACS | F4: Data / Workflow | G4: Consumes | H4: Critical | I4: Diagnostic images may not be available in clinical workflows. | J4: Imaging orders, reports, and links | K4: Low | L4: Validate image and report access. | M4: CMDB / interface catalog / synthetic assessment | N4: High | O4: Synthetic organization dependency
A5: DEP-004 | B5: APP-002 | C5: Oracle Health EHR | D5: APP-020 | E5: Imprivata Enterprise Access Management | F5: Authentication | G5: Consumes | H5: Critical | I5: Clinician access at acquired hospitals may be delayed. | J5: Identity assertions and badge authentication | K5: Medium | L5: Map access profiles to the target EHR. | M5: CMDB / interface catalog / synthetic assessment | N5: High | O5: Synthetic organization dependency
A6: DEP-005 | B6: APP-002 | C6: Oracle Health EHR | D6: EXT-001 | E6: Enterprise Integration Engine | F6: Data / Interface | G6: Consumes | H6: Critical | I6: Clinical feeds and results may fail during migration. | J6: HL7 and FHIR clinical messages | K6: High | L6: Migrate and reconcile interfaces before retirement. | M6: CMDB / interface catalog / synthetic assessment | N6: Medium | O6: Synthetic organization dependency
A7: DEP-006 | B7: APP-003 | C7: athenaOne | D7: EXT-003 | E7: Enterprise Identity Provider | F7: Authentication | G7: Consumes | H7: High | I7: Ambulatory users may lose SSO access. | J7: SAML and user provisioning | K7: Low | L7: Retain and monitor SSO integration. | M7: CMDB / interface catalog / synthetic assessment | N7: High | O7: Synthetic organization dependency
A8: DEP-007 | B8: APP-004 | C8: Microsoft Teams Enterprise | D8: EXT-003 | E8: Microsoft Entra ID | F8: Authentication | G8: Consumes | H8: High | I8: Enterprise collaboration access may fail. | J8: Identity, groups, and conditional access | K8: Low | L8: Maintain tenant identity resilience. | M8: CMDB / interface catalog / synthetic assessment | N8: High | O8: Synthetic organization dependency
A9: DEP-008 | B9: APP-005 | C9: Slack Enterprise Grid | D9: EXT-003 | E9: Microsoft Entra ID | F9: Authentication | G9: Consumes | H9: High | I9: Users may lose access to Slack. | J9: SAML and SCIM provisioning | K9: Low | L9: Remove provisioning after content migration. | M9: CMDB / interface catalog / synthetic assessment | N9: High | O9: Synthetic organization dependency
A10: DEP-009 | B10: APP-005 | C10: Slack Enterprise Grid | D10: APP-013 | E10: ServiceNow IT Service Management | F10: Workflow | G10: Consumes | H10: Medium | I10: Support alerts and approvals may not reach channels. | J10: Ticket alerts and workflow actions | K10: Medium | L10: Rebuild fourteen required workflows in Teams or ServiceNow. | M10: CMDB / interface catalog / synthetic assessment | N10: High | O10: Synthetic organization dependency
A11: DEP-010 | B11: APP-006 | C11: Zoom Workplace | D11: EXT-003 | E11: Microsoft Entra ID | F11: Authentication | G11: Consumes | H11: High | I11: Users may lose meeting access. | J11: SAML and user provisioning | K11: Low | L11: Remove provisioning only after disposition. | M11: CMDB / interface catalog / synthetic assessment | N11: High | O11: Synthetic organization dependency
A12: DEP-011 | B12: APP-006 | C12: Zoom Workplace | D12: EXT-004 | E12: Telehealth Scheduling Gateway | F12: Workflow | G12: Consumes | H12: High | I12: Patient video visits may fail or require manual scheduling. | J12: Appointment links and visit status | K12: High | L12: Validate target capability before committing savings. | M12: CMDB / interface catalog / synthetic assessment | N12: Medium | O12: Synthetic organization dependency
... A33: DEP-032 | B33: APP-020 | C33: Imprivata Enterprise Access Management | D33: EXT-009 | E33: Shared Clinical Workstations | F33: Infrastructure | G33: Provides | H33: Critical | I33: Clinicians may lose rapid access to clinical applications. | J33: Endpoint sessions and badge events | K33: Medium | L33: Test endpoint fallback and failover quarterly. | M33: CMDB / interface catalog / synthetic assessment | N33: High | O33: Synthetic organization dependency

Sheet Performance & Roadmap
A1: App ID | B1: Application Name | C1: Availability (12mo) | D1: SLA Target | E1: P1/P2 Incidents (12mo) | F1: MTTR (minutes) | G1: P95 Response Time (seconds) | H1: Business KPI | I1: KPI Actual | J1: KPI Target | K1: Performance Status | L1: Current Release / Version | M1: Lifecycle Stage | N1: Next Minor Release | O1: Next Major Update | P1: Vendor Support End | Q1: Contract Renewal Date | R1: Auto-Renew | S1: Exit Notice (days) | T1: Roadmap / Update Notes | U1: Evidence Source | V1: Evidence Confidence
A2: APP-001 | B2: Epic | C2: 0.9998 | D2: 0.999 | E2: 12 | F2: 42 | G2: 1.8 | H2: CPOE completion rate | I2: 0.985 | J2: 0.98 | K2: =IF(AND(C2>=D2,I2>=J2),"Meets","Below") -> Meets | L2: May 2026 (synthetic) | M2: Strategic Invest | N2: 2026-09-15 | O2: 2027-03-15 | Q2: 2027-06-30 | R2: No | S2: 180 | T2: Quarterly optimization and annual major upgrade. | U2: Monitoring, service desk, contract calendar, and vendor roadmap; synthetic values | V2: High
A3: APP-002 | B3: Oracle Health EHR | C3: 0.9985 | D3: 0.999 | E3: 37 | F3: 110 | G3: 2.9 | H3: CPOE completion rate | I3: 0.91 | J3: 0.98 | K3: =IF(AND(C3>=D3,I3>=J3),"Meets","Below") -> Below | L3: 2026.2 (synthetic) | M3: Consolidation Candidate | N3: 2026-09-30 | O3: 2027-02-01 | Q3: 2027-01-31 | R3: Yes | S3: 120 | T3: Freeze nonessential customization; prepare phased migration. | U3: Monitoring, service desk, contract calendar, and vendor roadmap; synthetic values | V3: High
A4: APP-003 | B4: athenaOne | C4: 0.9995 | D4: 0.999 | E4: 8 | F4: 55 | G4: 2 | H4: Clean claim acceptance rate | I4: 0.976 | J4: 0.96 | K4: =IF(AND(C4>=D4,I4>=J4),"Meets","Below") -> Meets | L4: Continuous SaaS | M4: Active | N4: 2026-09-20 | O4: 2026-11-15 | Q4: 2027-03-31 | R4: No | S4: 90 | T4: Continuous vendor releases with quarterly regression testing. | U4: Monitoring, service desk, contract calendar, and vendor roadmap; synthetic values | V4: High
A5: APP-004 | B5: Microsoft Teams Enterprise | C5: 0.9997 | D5: 0.999 | E5: 16 | F5: 35 | G5: 1.4 | H5: Monthly active adoption | I5: 0.83 | J5: 0.75 | K5: =IF(AND(C5>=D5,I5>=J5),"Meets","Below") -> Meets | L5: Continuous SaaS | M5: Strategic Invest | N5: 2026-09-10 | O5: 2026-10-10 | Q5: 2027-06-30 | R5: No | S5: 120 | T5: Monthly channel, meeting, security, and AI feature releases. | U5: Monitoring, service desk, contract calendar, and vendor roadmap; synthetic values | V5: High
A6: APP-005 | B6: Slack Enterprise Grid | C6: 0.9993 | D6: 0.999 | E6: 22 | F6: 64 | G6: 1.7 | H6: Monthly active adoption | I6: 0.49 | J6: 0.7 | K6: =IF(AND(C6>=D6,I6>=J6),"Meets","Below") -> Below | L6: Continuous SaaS | M6: Consolidation Candidate | N6: 2026-09-18 | O6: 2026-10-20 | Q6: 2026-12-31 | R6: Yes | S6: 90 | T6: Limit changes to security and migration requirements. | U6: Monitoring, service desk, contract calendar, and vendor roadmap; synthetic values | V6: High
A7: APP-006 | B7: Zoom Workplace | C7: 0.9994 | D7: 0.999 | E7: 18 | F7: 71 | G7: 1.9 | H7: Monthly active adoption | I7: 0.26 | J7: 0.5 | K7: =IF(AND(C7>=D7,I7>=J7),"Meets","Below") -> Below | L7: Continuous SaaS | M7: Review | N7: 2026-09-12 | O7: 2026-09-25 | Q7: 2026-11-30 | R7: Yes | S7: 60 | T7: Validate telehealth, room, and recording dependencies. | U7: Monitoring, service desk, contract calendar, and vendor roadmap; synthetic values | V7: Low
